Workbook

Sheet Income Statement
A1: INFOSYS LIMITED — Consolidated Income Statement (₹ in Crore)
A2: Particulars (₹ Crore) | B2: FY 2020 | C2: FY2021 | D2: FY2022 | E2: FY2023 | F2: FY2024 | G2: FY2025
A3: Revenue from Operations | B3: 90791 | C3: 100472 | D3: 121641 | E3: 146767 | F3: 153670 | G3: 162990
A4: Cost of Sales | B4: -60732 | C4: -65413 | D4: -81998 | E4: -102353 | F4: -107413 | G4: -113347
A5: Gross Profit | B5: =B3+B4 -> 30059 | C5: =C3+C4 -> 35059 | D5: =D3+D4 -> 39643 | E5: =E3+E4 -> 44414 | F5: =F3+F4 -> 46257 | G5: =G3+G4 -> 49643
A6: Operating Expenses
A7: Selling & Marketing Expenses | B7: -4711 | C7: -4627 | D7: -5156 | E7: -6249 | F7: -6973 | G7: -7588
A8: General & Administration Expenses | B8: -5974 | C8: -5810 | D8: -6472 | E8: -7260 | F8: -7537 | G8: -7631
A9: Total Operating Expenses | B9: =SUM(B7:B8) -> -10685 | C9: =SUM(C7:C8) -> -10437 | D9: =SUM(D7:D8) -> -11628 | E9: =SUM(E7:E8) -> -13509 | F9: =SUM(F7:F8) -> -14510 | G9: =SUM(G7:G8) -> -15219
A10: Operating Profit (EBIT) | B10: =B5+B9 -> 19374 | C10: =C5+C9 -> 24622 | D10: =D5+D9 -> 28015 | E10: =E5+E9 -> 30905 | F10: =F5+F9 -> 31747 | G10: =G5+G9 -> 34424
A11: Depreciation & Amortization | B11: 2893 | C11: 3267 | D11: 3476 | E11: 4225 | F11: 4678 | G11: 4812
A12: EBITDA | B12: =B10+B11 -> 22267 | C12: =C10+C11 -> 27889 | D12: =D10+D11 -> 31491 | E12: =E10+E11 -> 35130 | F12: =F10+F11 -> 36425 | G12: =G10+G11 -> 39236
A13: Other Income / Non-operating Income | B13: 2803 | C13: 2201 | D13: 2295 | E13: 2701 | F13: 4711 | G13: 3600
A14: Finance Cost | B14: -170 | C14: -195 | D14: -200 | E14: -284 | F14: -470 | G14: -416
A15: Profit Before Tax (PBT) | B15: =B10+B13+B14 -> 22007 | C15: =C10+C13+C14 -> 26628 | D15: =D10+D13+D14 -> 30110 | E15: =E10+E13+E14 -> 33322 | F15: =F10+F13+F14 -> 35988 | G15: =G10+G13+G14 -> 37608
A16: Tax Expense | B16: 5368 | C16: 7205 | D16: 7964 | E16: 9214 | F16: 9740 | G16: 10858
A17: Profit After Tax (PAT) or Profit for the Year | B17: =B15-B16 -> 16639 | C17: =C15-C16 -> 19423 | D17: =D15-D16 -> 22146 | E17: =E15-E16 -> 24108 | F17: =F15-F16 -> 26248 | G17: =G15-G16 -> 26750
A18: EPS — Basic (₹) | B18: 38.97 | C18: 45.61 | D18: 52.52 | E18: 57.63 | F18: 63.39 | G18: 64.5
A20: KEY MARGINS
A21: Gross Profit Margin % | B21: =B5/B3 -> 0.33107907 | C21: =C5/C3 -> 0.34894299 | D21: =D5/D3 -> 0.32590163 | E21: =E5/E3 -> 0.30261571 | F21: =F5/F3 -> 0.30101516 | G21: =G5/G3 -> 0.30457697
A22: EBITDA Margin % | B22: =B12/B3 -> 0.24525559 | C22: =C12/C3 -> 0.27757982 | D22: =D12/D3 -> 0.25888475 | E22: =E12/E3 -> 0.23935898 | F22: =F12/F3 -> 0.2370339 | G22: =G12/G3 -> 0.24072642
A23: EBIT Margin % | B23: =B10/B3 -> 0.2133912 | C23: =C10/C3 -> 0.2450633 | D23: =D10/D3 -> 0.23030886 | E23: =E10/E3 -> 0.21057186 | F23: =F10/F3 -> 0.20659205 | G23: =G10/G3 -> 0.21120314
A24: PAT Margin % | B24: =B17/B3 -> 0.18326706 | C24: =C17/C3 -> 0.19331754 | D24: =D17/D3 -> 0.18206033 | E24: =E17/E3 -> 0.16426036 | F24: =F17/F3 -> 0.17080757 | G24: =G17/G3 -> 0.1641205
A25: YoY Revenue Growth % | B25: =IFERROR((B3-A3)/A3, ) -> 0 | C25: =IFERROR((C3-B3)/B3, ) -> 0.10662951 | D25: =IFERROR((D3-C3)/C3, ) -> 0.21069552 | E25: =IFERROR((E3-D3)/D3, ) -> 0.20655864 | F25: =IFERROR((F3-E3)/E3, ) -> 0.047033734 | G25: =IFERROR((G3-F3)/F3, ) -> 0.060649444
A26: Effective Tax Rate | B26: =B16/B15 -> 0.24392239 | C26: =C16/C15 -> 0.27057984 | D26: =D16/D15 -> 0.26449684 | E26: =E16/E15 -> 0.27651401 | F26: =F16/F15 -> 0.27064577 | G26: =G16/G15 -> 0.28871517
A28: Note: Depreciation & Amortization is embedded within the reported function-wise expense categories such as Cost of Sales and Operating Expenses. Therefore, it is not deducted separately again in the main Income Statement. For analytical purposes, EBITDA is calculated by adding back the total Depreciation & Amortization expense to EBIT. The D&A figure is sourced from the Infosys Annual Report.
A33: Source: Infosys Annual Reports,Consolidated Financial Statements & Statutory reports

Sheet Balance Sheet
A1: INFOSYS LIMITED — Consolidated Balance Sheet (₹ in Crore)
A2: Particulars (₹ Crore) | B2: FY 2020 | C2: FY2021 | D2: FY2022 | E2: FY2023 | F2: FY2024 | G2: FY2025
A3: ASSETS
A4: A. NON-CURRENT ASSETS
A5: Fixed Assets | B5: 17557 | C5: 18276 | D5: 18314 | E5: 20516 | F5: 19215 | G5: 18903
A6: Goodwill & Intangible Assets | B6: 7186 | C6: 8151 | D6: 7902 | E6: 8997 | F6: 8700 | G6: 12872
A7: Non-current Investments | B7: 4137 | C7: 11863 | D7: 13651 | E7: 12569 | F7: 11708 | G7: 11059
A8: Other Non-current Assets | B8: 9312 | C8: 9363 | D8: 10833 | E8: 12853 | F8: 8759 | G8: 8970
A9: Total Non-Current Assets | B9: =SUM(B5:B8) -> 38192 | C9: =SUM(C5:C8) -> 47653 | D9: =SUM(D5:D8) -> 50700 | E9: =SUM(E5:E8) -> 54935 | F9: =SUM(F5:F8) -> 48382 | G9: =SUM(G5:G8) -> 51804
A11: B. CURRENT ASSETS
A12: Current Investments | B12: 4655 | C12: 2342 | D12: 6673 | E12: 6909 | F12: 12915 | G12: 12482
A13: Trade Receivables | B13: 18487 | C13: 19294 | D13: 22698 | E13: 25424 | F13: 30193 | G13: 31158
A14: Cash & Cash Equivalents | B14: 18649 | C14: 24714 | D14: 17472 | E14: 12173 | F14: 14786 | G14: 24455
A15: Other Current Assets | B15: 12785 | C15: 14383 | D15: 20342 | E15: 26375 | F15: 31538 | G15: 29004
A16: Total Current Assets | B16: =SUM(B12:B15) -> 54576 | C16: =SUM(C12:C15) -> 60733 | D16: =SUM(D12:D15) -> 67185 | E16: =SUM(E12:E15) -> 70881 | F16: =SUM(F12:F15) -> 89432 | G16: =SUM(G12:G15) -> 97099
A18: TOTAL ASSETS | B18: =SUM(B9+B16) -> 92768 | C18: =SUM(C9+C16) -> 108386 | D18: =SUM(D9+D16) -> 117885 | E18: =SUM(E9+E16) -> 125816 | F18: =SUM(F9+F16) -> 137814 | G18: =SUM(G9+G16) -> 148903
A20: EQUITY
A21: C. EQUITY
A22: Equity Share Capital | B22: 2122 | C22: 2124 | D22: 2098 | E22: 2069 | F22: 2071 | G22: 2073
A23: Other Equity (Reserves & Surplus) | B23: 63328 | C23: 74227 | D23: 73252 | E23: 73338 | F23: 86045 | G23: 93745
A24: Total Equity Attributable to Owners | B24: =B22+B23 -> 65450 | C24: =C22+C23 -> 76351 | D24: =D22+D23 -> 75350 | E24: =E22+E23 -> 75407 | F24: =F22+F23 -> 88116 | G24: =G22+G23 -> 95818
A25: Non-controlling Interests | B25: 394 | C25: 431 | D25: 386 | E25: 388 | F25: 345 | G25: 385
A26: Total Equity | B26: =B24+B25 -> 65844 | C26: =C24+C25 -> 76782 | D26: =D24+D25 -> 75736 | E26: =E24+E25 -> 75795 | F26: =F24+F25 -> 88461 | G26: =G24+G25 -> 96203
A28: LIABILITIES
A29: D. NON-CURRENT LIABILITIES
A30: Non-current Lease Liabilities | B30: 4014 | C30: 4587 | D30: 4602 | E30: 7057 | F30: 6400 | G30: 5772
A31: Other Non-Current Liabilities | B31: 2054 | C31: 3152 | D31: 3944 | E31: 3778 | F31: 4159 | G31: 4078
A32: Total Non-Current Liabilities | B32: =SUM(B30:B31) -> 6068 | C32: =SUM(C30:C31) -> 7739 | D32: =SUM(D30:D31) -> 8546 | E32: =SUM(E30:E31) -> 10835 | F32: =SUM(F30:F31) -> 10559 | G32: =SUM(G30:G31) -> 9850
A34: E. CURRENT LIABILITIES
A35: Trade Payables | B35: 2852 | C35: 2645 | D35: 4134 | E35: 3865 | F35: 3956 | G35: 4164
A36: Other Current Liabilities | B36: 18004 | C36: 21220 | D36: 29469 | E36: 35321 | F36: 34838 | G36: 38686
A37: Total Current Liabilities | B37: =SUM(B35:B36) -> 20856 | C37: =SUM(C35:C36) -> 23865 | D37: =SUM(D35:D36) -> 33603 | E37: =SUM(E35:E36) -> 39186 | F37: =SUM(F35:F36) -> 38794 | G37: =SUM(G35:G36) -> 42850
A39: TOTAL EQUITY & LIABILITIES | B39: =SUM(B26+B32+B37) -> 92768 | C39: =SUM(C26+C32+C37) -> 108386 | D39: =SUM(D26+D32+D37) -> 117885 | E39: =SUM(E26+E32+E37) -> 125816 | F39: =SUM(F26+F32+F37) -> 137814 | G39: =SUM(G26+G32+G37) -> 148903
A41: CHECK (Assets - Liabilities) = 0 | B41: =(B18-B39) -> 0 | C41: =(C18-C39) -> 0 | D41: =(D18-D39) -> 0 | E41: =(E18-E39) -> 0 | F41: =(F18-F39) -> 0 | G41: =(G18-G39) -> 0
A43: Source: Infosys Annual Reports,Consolidated Financial Statements

Sheet Cash Flow
A1: INFOSYS LIMITED — Consolidated Statement of Cash Flows — Indirect Method (₹ in Crore)
A2: Particulars (₹ Crore) | B2: FY 2020 | C2: FY 2021 | D2: FY 2022 | E2: FY 2023 | F2: FY 2024 | G2: FY 2025
A3: A. CASH FLOW FROM OPERATING ACTIVITIES
A4: Profit for the Year (PAT) | B4: 16639 | C4: =INDEX('Income Statement'!C:C, MATCH("Profit After Tax (PAT) or Profit for the Year", 'Income Statement'!A:A, 0)) -> 19423 | D4: =INDEX('Income Statement'!D:D, MATCH("Profit After Tax (PAT) or Profit for the Year", 'Income Statement'!A:A, 0)) -> 22146 | E4: =INDEX('Income Statement'!E:E, MATCH("Profit After Tax (PAT) or Profit for the Year", 'Income Statement'!A:A, 0)) -> 24108 | F4: =INDEX('Income Statement'!F:F, MATCH("Profit After Tax (PAT) or Profit for the Year", 'Income Statement'!A:A, 0)) -> 26248 | G4: =INDEX('Income Statement'!G:G, MATCH("Profit After Tax (PAT) or Profit for the Year", 'Income Statement'!A:A, 0)) -> 26750
A6: Adjustments — Non-Cash & Reclassifications
A7: Income Tax Expense | B7: 5368 | C7: 7205 | D7: 7964 | E7: 9214 | F7: 9740 | G7: 10858
A8: Depreciation & Amortization | B8: 2893 | C8: 3267 | D8: 3476 | E8: 4225 | F8: 4678 | G8: 4812
A9: Interest & Dividend Income | B9: -1613 | C9: -1615 | D9: -1645 | E9: -1817 | F9: -2067 | G9: -2570
A10: Finance Cost | B10: 170 | C10: 195 | D10: 200 | E10: 284 | F10: 470 | G10: 416
A11: Exchange Differences, net | B11: 184 | C11: -62 | D11: 119 | E11: 161 | F11: 76 | G11: 79
A12: Stock Compensation, Imairment & Other Adjustments | B12: 279 | C12: 432 | D12: 661 | E12: 1430 | F12: 378 | G12: 1246
A14: Changes in Working Capital
A15: Trade Receivables & Unbilled Revenue | B15: -3861 | C15: -1835 | D15: -7937 | E15: -7076 | F15: -2667 | G15: -1769
A16: Loans & Other Financial Assets | B16: 76 | C16: -534 | D16: -1914 | E16: -3108 | F16: -1172 | G16: -1024
A17: Trade Payables | B17: -373 | C17: -245 | D17: 1489 | E17: -279 | F17: 91 | G17: 176
A18: Loans & Other Financial Liabilities | B18: 1791 | C18: 3382 | D18: 6938 | E18: 4119 | F18: -1334 | G18: 2322
A20: Cash Generated from Operations | B20: =SUM(B4,B7:B12,B15:B18) -> 21553 | C20: =SUM(C4,C7:C12,C15:C18) -> 29613 | D20: =SUM(D4,D7:D12,D15:D18) -> 31497 | E20: =SUM(E4,E7:E12,E15:E18) -> 31261 | F20: =SUM(F4,F7:F12,F15:F18) -> 34441 | G20: =SUM(G4,G7:G12,G15:G18) -> 41296
A21: Income Taxes Paid | B21: -4550 | C21: -6389 | D21: -7612 | E21: -8794 | F21: -9231 | G21: -5602
A23: NET CASH FROM OPERATING ACTIVITIES (A) | B23: =SUM(B20:B21) -> 17003 | C23: =SUM(C20:C21) -> 23224 | D23: =SUM(D20:D21) -> 23885 | E23: =SUM(E20:E21) -> 22467 | F23: =SUM(F20:F21) -> 25210 | G23: =SUM(G20:G21) -> 35694
A25: B. CASH FLOW FROM INVESTING ACTIVITIES
A26: CapEx — PP&E & Intangibles | B26: -3307 | C26: -2107 | D26: -2161 | E26: -2579 | F26: -2201 | G26: -2237
A27: Acquisition of Business | B27: -1860 | C27: -1221 | D27: 0 | E27: -910 | F27: 0 | G27: -3155
A28: Interest & Dividend Received | B28: 1929 | C28: 1418 | D28: 1898 | E28: 1525 | F28: 1768 | G28: 2040
A29: Net Investment Activity | B29: 2999 | C29: -5546 | D29: -6153 | E29: 755 | F29: -4576 | G29: 1406
A31: NET CASH FROM INVESTING ACTIVITIES (B) | B31: =SUM(B26:B30) -> -239 | C31: =SUM(C26:C29) -> -7456 | D31: =SUM(D26:D29) -> -6416 | E31: =SUM(E26:E29) -> -1209 | F31: =SUM(F26:F29) -> -5009 | G31: =SUM(G26:G29) -> -1946
A33: C. CASH FLOW FROM FINANCING ACTIVITIES
A34: Dividends Paid | B34: -9515 | C34: -9117 | D34: -12652 | E34: -13631 | F34: -14692 | G34: -20287
A35: Payment of Lease Liabilities | B35: -571 | C35: -698 | D35: -915 | E35: -1231 | F35: -2024 | G35: -2355
A36: Buyback of Equity Shares | B36: -7478 | C36: 0 | D36: -11125 | E36: -11499 | F36: 0 | G36: 0
A37: Other Financing | B37: -27 | C37: 29 | D37: 50 | E37: -334 | F37: -788 | G37: -1519
A39: NET CASH FROM FINANCING ACTIVITIES (C) | B39: =SUM(B34:B37) -> -17591 | C39: =SUM(C34:C37) -> -9786 | D39: =SUM(D34:D37) -> -24642 | E39: =SUM(E34:E37) -> -26695 | F39: =SUM(F34:F37) -> -17504 | G39: =SUM(G34:G37) -> -24161
A41: D. NET CHANGE & CLOSING CASH
A42: Net Increase / (Decrease) in Cash | B42: =B23+B31+B39 -> -827 | C42: =C23+C31+C39 -> 5982 | D42: =D23+D31+D39 -> -7173 | E42: =E23+E31+E39 -> -5437 | F42: =F23+F31+F39 -> 2697 | G42: =G23+G31+G39 -> 9587
A43: Exchange Rate Effect on Cash | B43: -92 | C43: 83 | D43: -69 | E43: 138 | F43: -84 | G43: 82
A44: Cash at Beginning of Year | B44: 19568 | C44: =INDEX('Balance Sheet'!B:B,MATCH("Cash & Cash Equivalents",'Balance Sheet'!A:A,0)) -> 18649 | D44: =INDEX('Balance Sheet'!C:C,MATCH("Cash & Cash Equivalents",'Balance Sheet'!A:A,0)) -> 24714 | E44: =INDEX('Balance Sheet'!D:D,MATCH("Cash & Cash Equivalents",'Balance Sheet'!A:A,0)) -> 17472 | F44: =INDEX('Balance Sheet'!E:E,MATCH("Cash & Cash Equivalents",'Balance Sheet'!A:A,0)) -> 12173 | G44: =INDEX('Balance Sheet'!F:F,MATCH("Cash & Cash Equivalents",'Balance Sheet'!A:A,0)) -> 14786
A45: Cash at End of Year (CF Statement) | B45: =B42+B43+B44 -> 18649 | C45: =C42+C43+C44 -> 24714 | D45: =D42+D43+D44 -> 17472 | E45: =E42+E43+E44 -> 12173 | F45: =F42+F43+F44 -> 14786 | G45: =G42+G43+G44 -> 24455
A47: E. KEY METRICS
A48: Free Cash Flow = CFO + CapEx | B48: =B23+B26 -> 13696 | C48: =C23+C26 -> 21117 | D48: =D23+D26 -> 21724 | E48: =E23+E26 -> 19888 | F48: =F23+F26 -> 23009 | G48: =G23+G26 -> 33457
A49: FCF Margin % (FCF ÷ Revenue) | B49: =B48/'Income Statement'!B3 -> 0.15085196 | C49: =C48/'Income Statement'!C3 -> 0.21017796 | D49: =D48/'Income Statement'!D3 -> 0.1785911 | E49: =E48/'Income Statement'!E3 -> 0.1355073 | F49: =F48/'Income Statement'!F3 -> 0.14972994 | G49: =G48/'Income Statement'!G3 -> 0.20527026
A50: CFO to PAT (Cash Quality Ratio) | B50: =B23/'Income Statement'!B17 -> 1.0218763 | C50: =C23/'Income Statement'!C17 -> 1.1956958 | D50: =D23/'Income Statement'!D17 -> 1.0785243 | E50: =E23/'Income Statement'!E17 -> 0.93193131 | F50: =F23/'Income Statement'!F17 -> 0.96045413 | G50: =G23/'Income Statement'!G17 -> 1.3343551
...

Sheet Ratio Analysis
A1: INFOSYS LIMITED − Ratio Analysis (FY 2020 to FY 2025)
A2: Ratio | B2: FY 2021 | C2: FY 2022 | D2: FY 2023 | E2: FY 2024 | F2: FY 2025
A3: 1. GROWTH RATIOS ─ Is Infosys growing consistently over time?
A4: Revenue Growth YoY | B4: =('Income Statement'!C3-'Income Statement'!B3)/'Income Statement'!B3 -> 0.10662951 | C4: =('Income Statement'!D3-'Income Statement'!C3)/'Income Statement'!C3 -> 0.21069552 | D4: =('Income Statement'!E3-'Income Statement'!D3)/'Income Statement'!D3 -> 0.20655864 | E4: =('Income Statement'!F3-'Income Statement'!E3)/'Income Statement'!E3 -> 0.047033734 | F4: =('Income Statement'!G3-'Income Statement'!F3)/'Income Statement'!F3 -> 0.060649444
A5: PAT Growth YoY | B5: =('Income Statement'!C17-'Income Statement'!B17)/'Income Statement'!B17 -> 0.16731775 | C5: =('Income Statement'!D17-'Income Statement'!C17)/'Income Statement'!C17 -> 0.14019461 | D5: =('Income Statement'!E17-'Income Statement'!D17)/'Income Statement'!D17 -> 0.088593877 | E5: =('Income Statement'!F17-'Income Statement'!E17)/'Income Statement'!E17 -> 0.088767214 | F5: =('Income Statement'!G17-'Income Statement'!F17)/'Income Statement'!F17 -> 0.019125267
A6: EPS Growth YoY | B6: =('Income Statement'!C18-'Income Statement'!B18)/'Income Statement'!B18 -> 0.17038748 | C6: =('Income Statement'!D18-'Income Statement'!C18)/'Income Statement'!C18 -> 0.15150186 | D6: =('Income Statement'!E18-'Income Statement'!D18)/'Income Statement'!D18 -> 0.097296268 | E6: =('Income Statement'!F18-'Income Statement'!E18)/'Income Statement'!E18 -> 0.099947944 | F6: =('Income Statement'!G18-'Income Statement'!F18)/'Income Statement'!F18 -> 0.017510648
A7: FCF Growth YoY | B7: =('Cash Flow'!C48-'Cash Flow'!B48)/'Cash Flow'!B48 -> 0.54183703 | C7: =('Cash Flow'!D48-'Cash Flow'!C48)/'Cash Flow'!C48 -> 0.028744613 | D7: =('Cash Flow'!E48-'Cash Flow'!D48)/'Cash Flow'!D48 -> -0.084514822 | E7: =('Cash Flow'!F48-'Cash Flow'!E48)/'Cash Flow'!E48 -> 0.1569288 | F7: =('Cash Flow'!G48-'Cash Flow'!F48)/'Cash Flow'!F48 -> 0.45408318
A8: 5-Year Revenue CAGR | B8: 0 | C8: 0 | D8: 0 | E8: 0 | F8: =('Income Statement'!G3/'Income Statement'!C3)^(1/4)-1 -> 0.12857124
A9: 5-Year PAT CAGR | B9: 0 | C9: 0 | D9: 0 | E9: 0 | F9: =('Income Statement'!G17/'Income Statement'!C17)^(1/4)-1 -> 0.083307797
A11: 2.PROFITABILITY RATIOS ─ How well does Infosys convert revenue into profit ?
A12: Gross Profit Margin | B12: ='Income Statement'!C5/'Income Statement'!C3 -> 0.34894299 | C12: ='Income Statement'!D5/'Income Statement'!D3 -> 0.32590163 | D12: ='Income Statement'!E5/'Income Statement'!E3 -> 0.30261571 | E12: ='Income Statement'!F5/'Income Statement'!F3 -> 0.30101516 | F12: ='Income Statement'!G5/'Income Statement'!G3 -> 0.30457697
A13: EBITDA Margin | B13: ='Income Statement'!C12/'Income Statement'!C3 -> 0.27757982 | C13: ='Income Statement'!D12/'Income Statement'!D3 -> 0.25888475 | D13: ='Income Statement'!E12/'Income Statement'!E3 -> 0.23935898 | E13: ='Income Statement'!F12/'Income Statement'!F3 -> 0.2370339 | F13: ='Income Statement'!G12/'Income Statement'!G3 -> 0.24072642
A14: EBIT (Operating) Margin | B14: ='Income Statement'!C10/'Income Statement'!C3 -> 0.2450633 | C14: ='Income Statement'!D10/'Income Statement'!D3 -> 0.23030886 | D14: ='Income Statement'!E10/'Income Statement'!E3 -> 0.21057186 | E14: ='Income Statement'!F10/'Income Statement'!F3 -> 0.20659205 | F14: ='Income Statement'!G10/'Income Statement'!G3 -> 0.21120314
A15: PAT (Net Profit) Margin | B15: ='Income Statement'!C17/'Income Statement'!C3 -> 0.19331754 | C15: ='Income Statement'!D17/'Income Statement'!D3 -> 0.18206033 | D15: ='Income Statement'!E17/'Income Statement'!E3 -> 0.16426036 | E15: ='Income Statement'!F17/'Income Statement'!F3 -> 0.17080757 | F15: ='Income Statement'!G17/'Income Statement'!G3 -> 0.1641205
A16: Return on Equity (ROE) | B16: =('Income Statement'!C17/(('Balance Sheet'!C26+'Balance Sheet'!B26)/2)) -> 0.27236268 | C16: =('Income Statement'!D17/(('Balance Sheet'!D26+'Balance Sheet'!C26)/2)) -> 0.29040507 | D16: =('Income Statement'!E17/(('Balance Sheet'!E26+'Balance Sheet'!D26)/2)) -> 0.31819232 | E16: =('Income Statement'!F17/(('Balance Sheet'!F26+'Balance Sheet'!E26)/2)) -> 0.31959868 | F16: =('Income Statement'!G17/(('Balance Sheet'!G26+'Balance Sheet'!F26)/2)) -> 0.28971537
A17: Return on Assets (ROA) | B17: =('Income Statement'!C17/(('Balance Sheet'!C18+'Balance Sheet'!B18)/2)) -> 0.19311572 | C17: =('Income Statement'!D17/(('Balance Sheet'!D18+'Balance Sheet'!C18)/2)) -> 0.19574758 | D17: =('Income Statement'!E17/(('Balance Sheet'!E18+'Balance Sheet'!D18)/2)) -> 0.197849 | E17: =('Income Statement'!F17/(('Balance Sheet'!F18+'Balance Sheet'!E18)/2)) -> 0.19912757 | F17: =('Income Statement'!G17/(('Balance Sheet'!G18+'Balance Sheet'!F18)/2)) -> 0.18659514
A18: Return on Capital Employed (ROCE) | B18: =('Income Statement'!C10/('Balance Sheet'!C18-'Balance Sheet'!C32)) -> 0.2446372 | C18: =('Income Statement'!D10/('Balance Sheet'!D18-'Balance Sheet'!D32)) -> 0.25622148 | D18: =('Income Statement'!E10/('Balance Sheet'!E18-'Balance Sheet'!E32)) -> 0.26878354 | E18: =('Income Statement'!F10/('Balance Sheet'!F18-'Balance Sheet'!F32)) -> 0.24947546 | F18: =('Income Statement'!G10/('Balance Sheet'!G18-'Balance Sheet'!G32)) -> 0.24756028
A20: 3. LIQUIDITY RATIOS ─ Can Infosys meet its short-term obligations?
A21: Current Ratio | B21: ='Balance Sheet'!C16/'Balance Sheet'!C37 -> 2.5448565 | C21: ='Balance Sheet'!D16/'Balance Sheet'!D37 -> 1.9993751 | D21: ='Balance Sheet'!E16/'Balance Sheet'!E37 -> 1.8088348 | E21: ='Balance Sheet'!F16/'Balance Sheet'!F37 -> 2.3053049 | F21: ='Balance Sheet'!G16/'Balance Sheet'!G37 -> 2.266021
A22: Quick Ratio (Acid Test) | B22: =('Balance Sheet'!C12+'Balance Sheet'!C13+'Balance Sheet'!C14)/'Balance Sheet'!C37 -> 1.9421747 | C22: =('Balance Sheet'!D12+'Balance Sheet'!D13+'Balance Sheet'!D14)/'Balance Sheet'!D37 -> 1.3940124 | D22: =('Balance Sheet'!E12+'Balance Sheet'!E13+'Balance Sheet'!E14)/'Balance Sheet'!E37 -> 1.1357628 | E22: =('Balance Sheet'!F12+'Balance Sheet'!F13+'Balance Sheet'!F14)/'Balance Sheet'!F37 -> 1.4923442 | F22: =('Balance Sheet'!G12+'Balance Sheet'!G13+'Balance Sheet'!G14)/'Balance Sheet'!G37 -> 1.5891482
A23: Cash Ratio | B23: =('Balance Sheet'!C14+'Balance Sheet'!C12)/'Balance Sheet'!C37 -> 1.1337105 | C23: =('Balance Sheet'!D14+'Balance Sheet'!D12)/'Balance Sheet'!D37 -> 0.71853704 | D23: =('Balance Sheet'!E14+'Balance Sheet'!E12)/'Balance Sheet'!E37 -> 0.48695963 | E23: =('Balance Sheet'!F14+'Balance Sheet'!F12)/'Balance Sheet'!F37 -> 0.71405372 | F23: =('Balance Sheet'!G14+'Balance Sheet'!G12)/'Balance Sheet'!G37 -> 0.862007
A25: 4. EFFICIENCY RATIOS ─ How effectively does Infosys use its assets?
A26: Day Sales Outstanding (DSO) | B26: =(('Balance Sheet'!C13+'Balance Sheet'!B13)/2)/'Income Statement'!C3*365 -> 68.626408 | C26: =(('Balance Sheet'!D13+'Balance Sheet'!C13)/2)/'Income Statement'!D3*365 -> 63.001291 | D26: =(('Balance Sheet'!E13+'Balance Sheet'!D13)/2)/'Income Statement'!E3*365 -> 59.838145 | E26: =(('Balance Sheet'!F13+'Balance Sheet'!E13)/2)/'Income Statement'!F3*365 -> 66.051295 | F26: =(('Balance Sheet'!G13+'Balance Sheet'!F13)/2)/'Income Statement'!G3*365 -> 68.694751
A27: Day Payables Outstanding (DPO) | B27: =ABS((('Balance Sheet'!C35+'Balance Sheet'!B35)/2)/'Income Statement'!C4*365) -> 15.336439 | C27: =ABS((('Balance Sheet'!D35+'Balance Sheet'!C35)/2)/'Income Statement'!D4*365) -> 15.087777 | D27: =ABS((('Balance Sheet'!E35+'Balance Sheet'!D35)/2)/'Income Statement'!E4*365) -> 14.262577 | E27: =ABS((('Balance Sheet'!F35+'Balance Sheet'!E35)/2)/'Income Statement'!F4*365) -> 13.288266 | F27: =ABS((('Balance Sheet'!G35+'Balance Sheet'!F35)/2)/'Income Statement'!G4*365) -> 13.074012
A28: Asset Turnover ratio | B28: ='Income Statement'!C3/(('Balance Sheet'!B18+'Balance Sheet'!C18)/2) -> 0.99895602 | C28: ='Income Statement'!D3/(('Balance Sheet'!C18+'Balance Sheet'!D18)/2) -> 1.0751798 | D28: ='Income Statement'!E3/(('Balance Sheet'!D18+'Balance Sheet'!E18)/2) -> 1.2044842 | E28: ='Income Statement'!F3/(('Balance Sheet'!E18+'Balance Sheet'!F18)/2) -> 1.1658006 | F28: ='Income Statement'!G3/(('Balance Sheet'!F18+'Balance Sheet'!G18)/2) -> 1.1369399
A29: Fixed Asset Turnover | B29: ='Income Statement'!C3/(('Balance Sheet'!B5+'Balance Sheet'!C5)/2) -> 5.6077917 | C29: ='Income Statement'!D3/(('Balance Sheet'!C5+'Balance Sheet'!D5)/2) -> 6.6488658 | D29: ='Income Statement'!E3/(('Balance Sheet'!D5+'Balance Sheet'!E5)/2) -> 7.5594643 | E29: ='Income Statement'!F3/(('Balance Sheet'!E5+'Balance Sheet'!F5)/2) -> 7.7355214 | F29: ='Income Statement'!G3/(('Balance Sheet'!F5+'Balance Sheet'!G5)/2) -> 8.5518653
A30: Working Capital Turnover | B30: ='Income Statement'!C3/(('Balance Sheet'!B16-'Balance Sheet'!B37)+('Balance Sheet'!C16-'Balance Sheet'!C37)/2) -> 1.9264486 | C30: ='Income Statement'!D3/(('Balance Sheet'!C16-'Balance Sheet'!C37)+('Balance Sheet'!D16-'Balance Sheet'!D37)/2) -> 2.2669263 | D30: ='Income Statement'!E3/(('Balance Sheet'!D16-'Balance Sheet'!D37)+('Balance Sheet'!E16-'Balance Sheet'!E37)/2) -> 2.9692188 | E30: ='Income Statement'!F3/(('Balance Sheet'!E16-'Balance Sheet'!E37)+('Balance Sheet'!F16-'Balance Sheet'!F37)/2) -> 2.6953029 | F30: ='Income Statement'!G3/(('Balance Sheet'!F16-'Balance Sheet'!F37)+('Balance Sheet'!G16-'Balance Sheet'!G37)/2) -> 2.0959974
A32: 5. SOLVENCY RATIOS ─ Is Infosys financially stable long-term?
A33: Debt-to-Equity Ratio | B33: =('Balance Sheet'!C39-'Balance Sheet'!C26)/'Balance Sheet'!C26 -> 0.41160689 | C33: =('Balance Sheet'!D39-'Balance Sheet'!D26)/'Balance Sheet'!D26 -> 0.5565253 | D33: =('Balance Sheet'!E39-'Balance Sheet'!E26)/'Balance Sheet'!E26 -> 0.65995118 | E33: =('Balance Sheet'!F39-'Balance Sheet'!F26)/'Balance Sheet'!F26 -> 0.55790687 | F33: =('Balance Sheet'!G39-'Balance Sheet'!G26)/'Balance Sheet'!G26 -> 0.54779996
A34: Debt-to-Assets Ratio | B34: =('Balance Sheet'!C39-'Balance Sheet'!C26)/'Balance Sheet'!C18 -> 0.29158747 | C34: =('Balance Sheet'!D39-'Balance Sheet'!D26)/'Balance Sheet'!D18 -> 0.35754337 | D34: =('Balance Sheet'!E39-'Balance Sheet'!E26)/'Balance Sheet'!E18 -> 0.39757265 | E34: =('Balance Sheet'!F39-'Balance Sheet'!F26)/'Balance Sheet'!F18 -> 0.35811311 | F34: =('Balance Sheet'!G39-'Balance Sheet'!G26)/'Balance Sheet'!G18 -> 0.35392168
A35: Interest Coverage Ratio | B35: =ABS('Income Statement'!C10/'Income Statement'!C14) -> 126.26667 | C35: =ABS('Income Statement'!D10/'Income Statement'!D14) -> 140.075 | D35: =ABS('Income Statement'!E10/'Income Statement'!E14) -> 108.82042 | E35: =ABS('Income Statement'!F10/'Income Statement'!F14) -> 67.546809 | F35: =ABS('Income Statement'!G10/'Income Statement'!G14) -> 82.75
A36: Equity Multiplier | B36: ='Balance Sheet'!C18/'Balance Sheet'!C26 -> 1.4116069 | C36: ='Balance Sheet'!D18/'Balance Sheet'!D26 -> 1.5565253 | D36: ='Balance Sheet'!E18/'Balance Sheet'!E26 -> 1.6599512 | E36: ='Balance Sheet'!F18/'Balance Sheet'!F26 -> 1.5579069 | F36: ='Balance Sheet'!G18/'Balance Sheet'!G26 -> 1.5478
A38: 6. CASHFLOW RATIOS ─ Is Infosys's profit backed by real cash?
A39: CFO to PAT (Earnings Quality) | B39: ='Cash Flow'!C23/'Cash Flow'!C4 -> 1.1956958 | C39: ='Cash Flow'!D23/'Cash Flow'!D4 -> 1.0785243 | D39: ='Cash Flow'!E23/'Cash Flow'!E4 -> 0.93193131 | E39: ='Cash Flow'!F23/'Cash Flow'!F4 -> 0.96045413 | F39: ='Cash Flow'!G23/'Cash Flow'!G4 -> 1.3343551
A40: Free Cash Flow (FCF) | B40: ='Cash Flow'!C23-ABS('Cash Flow'!C26) -> 21117 | C40: ='Cash Flow'!D23-ABS('Cash Flow'!D26) -> 21724 | D40: ='Cash Flow'!E23-ABS('Cash Flow'!E26) -> 19888 | E40: ='Cash Flow'!F23-ABS('Cash Flow'!F26) -> 23009 | F40: ='Cash Flow'!G23-ABS('Cash Flow'!G26) -> 33457
A41: FCF Margin | B41: =B40/'Income Statement'!C3 -> 0.21017796 | C41: =C40/'Income Statement'!D3 -> 0.1785911 | D41: =D40/'Income Statement'!E3 -> 0.1355073 | E41: =E40/'Income Statement'!F3 -> 0.14972994 | F41: =F40/'Income Statement'!G3 -> 0.20527026
A42: CapEx to CFO (Reinvestment Rate) | B42: =ABS('Cash Flow'!C26)/'Cash Flow'!C23 -> 0.090725112 | C42: =ABS('Cash Flow'!D26)/'Cash Flow'!D23 -> 0.090475194 | D42: =ABS('Cash Flow'!E26)/'Cash Flow'!E23 -> 0.11479058 | E42: =ABS('Cash Flow'!F26)/'Cash Flow'!F23 -> 0.087306624 | F42: =ABS('Cash Flow'!G26)/'Cash Flow'!G23 -> 0.062671597
A43: Cash Return to Shareholders % | B43: =ABS('Cash Flow'!C34)/'Cash Flow'!C23 -> 0.39256803 | C43: =ABS('Cash Flow'!D34)/'Cash Flow'!D23 -> 0.52970484 | D43: =ABS('Cash Flow'!E34)/'Cash Flow'!E23 -> 0.60671207 | E43: =ABS('Cash Flow'!F34)/'Cash Flow'!F23 -> 0.58278461 | F43: =ABS('Cash Flow'!G34)/'Cash Flow'!G23 -> 0.56835883
A45: 7. DuPont Analysis ─ Decomposing ROE into 3 drivers
A46: Net Profit Margin (Driver 1) | B46: ='Income Statement'!C17/'Income Statement'!C3 -> 0.19331754 | C46: ='Income Statement'!D17/'Income Statement'!D3 -> 0.18206033 | D46: ='Income Statement'!E17/'Income Statement'!E3 -> 0.16426036 | E46: ='Income Statement'!F17/'Income Statement'!F3 -> 0.17080757 | F46: ='Income Statement'!G17/'Income Statement'!G3 -> 0.1641205
...
